<sdf version='1.7'>
  <model name='beetle'>
    <link name='base_link'>
      <inertial>
        <pose>0.690274 0 2.5e-05 0 -0 0</pose>
        <mass>40.1</mass>
        <inertia>
          <ixx>2.03351</ixx>
          <ixy>0</ixy>
          <ixz>0.000690274</ixz>
          <iyy>13.2536</iyy>
          <iyz>0</iyz>
          <izz>15.2763</izz>
        </inertia>
      </inertial>
      <collision name='base_link_collision'>
        <pose>0.692 0 0 0 -0 0</pose>
        <geometry>
          <box>
            <size>1.99 0.78 0.04</size>
          </box>
        </geometry>
      </collision>
      <collision name='base_link_fixed_joint_lump__imu_link_collision_1'>
        <pose>0 0 0.01 0 -0 0</pose>
        <geometry>
          <box>
            <size>0.1 0.1 0.1</size>
          </box>
        </geometry>
        <surface>
          <contact>
            <ode/>
          </contact>
          <friction>
            <ode/>
          </friction>
        </surface>
      </collision>
      <visual name='base_link_visual'>
        <pose>0.317 0 0 0 -0 0</pose>
        <geometry>
          <box>
            <size>1.24 0.78 0.04</size>
          </box>
        </geometry>
      </visual>
      <visual name='base_link_visual_1'>
        <pose>1.192 0 0 0 -0 0</pose>
        <geometry>
          <box>
            <size>0.51 0.38 0.04</size>
          </box>
        </geometry>
      </visual>
      <visual name='base_link_visual_2'>
        <pose>1.567 0 0 0 -0 0</pose>
        <geometry>
          <box>
            <size>0.24 0.78 0.04</size>
          </box>
        </geometry>
      </visual>
      <visual name='base_link_fixed_joint_lump__imu_link_visual_3'>
        <pose>0 0 0.01 0 -0 0</pose>
        <geometry>
          <box>
            <size>0.1 0.1 0.1</size>
          </box>
        </geometry>
      </visual>
      <sensor name='imu_sensor' type='imu'>
        <plugin name='imu_plugin' filename='libgazebo_ros_imu_sensor.so'>
          <ros>
            <remapping>~/out:=/imu</remapping>
          </ros>
          <initial_orientation_as_reference>0</initial_orientation_as_reference>
        </plugin>
        <always_on>1</always_on>
        <update_rate>100</update_rate>
        <visualize>1</visualize>
        <imu>
          <angular_velocity>
            <x>
              <noise type='gaussian'>
                <mean>0</mean>
                <stddev>0.0002</stddev>
                <bias_mean>7.5e-06</bias_mean>
                <bias_stddev>8e-07</bias_stddev>
              </noise>
            </x>
            <y>
              <noise type='gaussian'>
                <mean>0</mean>
                <stddev>0.0002</stddev>
                <bias_mean>7.5e-06</bias_mean>
                <bias_stddev>8e-07</bias_stddev>
              </noise>
            </y>
            <z>
              <noise type='gaussian'>
                <mean>0</mean>
                <stddev>0.0002</stddev>
                <bias_mean>7.5e-06</bias_mean>
                <bias_stddev>8e-07</bias_stddev>
              </noise>
            </z>
          </angular_velocity>
          <linear_acceleration>
            <x>
              <noise type='gaussian'>
                <mean>0</mean>
                <stddev>0.017</stddev>
                <bias_mean>0.1</bias_mean>
                <bias_stddev>0.001</bias_stddev>
              </noise>
            </x>
            <y>
              <noise type='gaussian'>
                <mean>0</mean>
                <stddev>0.017</stddev>
                <bias_mean>0.1</bias_mean>
                <bias_stddev>0.001</bias_stddev>
              </noise>
            </y>
            <z>
              <noise type='gaussian'>
                <mean>0</mean>
                <stddev>0.017</stddev>
                <bias_mean>0.1</bias_mean>
                <bias_stddev>0.001</bias_stddev>
              </noise>
            </z>
          </linear_acceleration>
        </imu>
        <pose>0 0 0.01 0 -0 0</pose>
      </sensor>
    </link>
    <joint name='front_left_wheel_joint' type='revolute'>
      <pose relative_to='base_link'>1.19 0.533 -0.305 -1.5708 0 0</pose>
      <parent>base_link</parent>
      <child>front_left_wheel_link</child>
      <axis>
        <xyz>1 0 0</xyz>
        <limit>
          <lower>-1e+16</lower>
          <upper>1e+16</upper>
        </limit>
        <dynamics>
          <spring_reference>0</spring_reference>
          <spring_stiffness>0</spring_stiffness>
        </dynamics>
      </axis>
    </joint>
    <link name='front_left_wheel_link'>
      <pose relative_to='front_left_wheel_joint'>0 0 0 0 -0 0</pose>
      <inertial>
        <pose>0 0 0 0 -0 0</pose>
        <mass>8</mass>
        <inertia>
          <ixx>0.133067</ixx>
          <ixy>0</ixy>
          <ixz>0</ixz>
          <iyy>0.133067</iyy>
          <iyz>0</iyz>
          <izz>0.25</izz>
        </inertia>
      </inertial>
      <collision name='front_left_wheel_link_collision'>
        <pose>0 0 0 0 -0 0</pose>
        <geometry>
          <cylinder>
            <length>0.11</length>
            <radius>0.25</radius>
          </cylinder>
        </geometry>
      </collision>
      <visual name='front_left_wheel_link_visual'>
        <pose>0 0 0 0 -0 0</pose>
        <geometry>
          <cylinder>
            <length>0.11</length>
            <radius>0.25</radius>
          </cylinder>
        </geometry>
      </visual>
    </link>
    <joint name='front_right_wheel_joint' type='revolute'>
      <pose relative_to='base_link'>1.19 -0.533 -0.305 1.5708 -0 0</pose>
      <parent>base_link</parent>
      <child>front_right_wheel_link</child>
      <axis>
        <xyz>1 0 0</xyz>
        <limit>
          <lower>-1e+16</lower>
          <upper>1e+16</upper>
        </limit>
        <dynamics>
          <spring_reference>0</spring_reference>
          <spring_stiffness>0</spring_stiffness>
        </dynamics>
      </axis>
    </joint>
    <link name='front_right_wheel_link'>
      <pose relative_to='front_right_wheel_joint'>0 0 0 0 -0 0</pose>
      <inertial>
        <pose>0 0 0 0 -0 0</pose>
        <mass>8</mass>
        <inertia>
          <ixx>0.133067</ixx>
          <ixy>0</ixy>
          <ixz>0</ixz>
          <iyy>0.133067</iyy>
          <iyz>0</iyz>
          <izz>0.25</izz>
        </inertia>
      </inertial>
      <collision name='front_right_wheel_link_collision'>
        <pose>0 0 0 0 -0 0</pose>
        <geometry>
          <cylinder>
            <length>0.11</length>
            <radius>0.25</radius>
          </cylinder>
        </geometry>
      </collision>
      <visual name='front_right_wheel_link_visual'>
        <pose>0 0 0 0 -0 0</pose>
        <geometry>
          <cylinder>
            <length>0.11</length>
            <radius>0.25</radius>
          </cylinder>
        </geometry>
      </visual>
    </link>
    <joint name='rear_left_wheel_joint' type='revolute'>
      <pose relative_to='base_link'>0 0.533 -0.305 -1.5708 0 0</pose>
      <parent>base_link</parent>
      <child>rear_left_wheel_link</child>
      <axis>
        <xyz>1 0 0</xyz>
        <limit>
          <lower>-1e+16</lower>
          <upper>1e+16</upper>
        </limit>
        <dynamics>
          <spring_reference>0</spring_reference>
          <spring_stiffness>0</spring_stiffness>
        </dynamics>
      </axis>
    </joint>
    <link name='rear_left_wheel_link'>
      <pose relative_to='rear_left_wheel_joint'>0 0 0 0 -0 0</pose>
      <inertial>
        <pose>0 0 0 0 -0 0</pose>
        <mass>8</mass>
        <inertia>
          <ixx>0.133067</ixx>
          <ixy>0</ixy>
          <ixz>0</ixz>
          <iyy>0.133067</iyy>
          <iyz>0</iyz>
          <izz>0.25</izz>
        </inertia>
      </inertial>
      <collision name='rear_left_wheel_link_collision'>
        <pose>0 0 0 0 -0 0</pose>
        <geometry>
          <cylinder>
            <length>0.11</length>
            <radius>0.25</radius>
          </cylinder>
        </geometry>
      </collision>
      <visual name='rear_left_wheel_link_visual'>
        <pose>0 0 0 0 -0 0</pose>
        <geometry>
          <cylinder>
            <length>0.11</length>
            <radius>0.25</radius>
          </cylinder>
        </geometry>
      </visual>
    </link>
    <joint name='rear_right_wheel_joint' type='revolute'>
      <pose relative_to='base_link'>0 -0.533 -0.305 1.5708 -0 0</pose>
      <parent>base_link</parent>
      <child>rear_right_wheel_link</child>
      <axis>
        <xyz>1 0 0</xyz>
        <limit>
          <lower>-1e+16</lower>
          <upper>1e+16</upper>
        </limit>
        <dynamics>
          <spring_reference>0</spring_reference>
          <spring_stiffness>0</spring_stiffness>
        </dynamics>
      </axis>
    </joint>
    <link name='rear_right_wheel_link'>
      <pose relative_to='rear_right_wheel_joint'>0 0 0 0 -0 0</pose>
      <inertial>
        <pose>0 0 0 0 -0 0</pose>
        <mass>8</mass>
        <inertia>
          <ixx>0.133067</ixx>
          <ixy>0</ixy>
          <ixz>0</ixz>
          <iyy>0.133067</iyy>
          <iyz>0</iyz>
          <izz>0.25</izz>
        </inertia>
      </inertial>
      <collision name='rear_right_wheel_link_collision'>
        <pose>0 0 0 0 -0 0</pose>
        <geometry>
          <cylinder>
            <length>0.11</length>
            <radius>0.25</radius>
          </cylinder>
        </geometry>
      </collision>
      <visual name='rear_right_wheel_link_visual'>
        <pose>0 0 0 0 -0 0</pose>
        <geometry>
          <cylinder>
            <length>0.11</length>
            <radius>0.25</radius>
          </cylinder>
        </geometry>
      </visual>
    </link>
  </model>
</sdf>
