<?xml version="1.0" ?>
<!-- =================================================================================== -->
<!-- |    This document was autogenerated by xacro from src/beetle_description/urdf/beetle.urdf | -->
<!-- |    EDITING THIS FILE BY HAND IS NOT RECOMMENDED                                 | -->
<!-- =================================================================================== -->
<robot name="beetle">
  <gazebo>
    <plugin filename="libgazebo_ros_control.so" name="gazebo_ros_control">
      <robotNamespace>/beetle</robotNamespace>
    </plugin>
  </gazebo>
  <!-- Define other macros  -->
  <!-- Robot Base -->
  <link name="base_link">
    <visual>
      <origin xyz="0.317 0 0"/>
      <geometry>
        <box size="1.24 0.78 0.04"/>
      </geometry>
      <material name="Cyan">
        <color rgba="0 1.0 1.0 1.0"/>
      </material>
    </visual>
    <visual>
      <origin xyz="1.1920000000000002 0 0"/>
      <geometry>
        <box size="0.51 0.38 0.04"/>
      </geometry>
      <material name="Cyan">
        <color rgba="0 1.0 1.0 1.0"/>
      </material>
    </visual>
    <visual>
      <origin xyz="1.5670000000000002 0 0"/>
      <geometry>
        <box size="0.24 0.78 0.04"/>
      </geometry>
      <material name="Cyan">
        <color rgba="0 1.0 1.0 1.0"/>
      </material>
    </visual>
    <collision>
      <origin xyz="0.692 0 0"/>
      <geometry>
        <box size="1.99 0.78 0.04"/>
      </geometry>
    </collision>
    <inertial>
      <origin xyz="0.692 0 0"/>
      <mass value="40.0"/>
      <inertia ixx="2.0333333333333337" ixy="0.0" ixz="0.0" iyy="13.205666666666668" iyz="0.0" izz="15.228333333333335"/>
    </inertial>
  </link>
  <!-- Robot Footprint -->
  <link name="base_footprint"/>
  <joint name="base_joint" type="fixed">
    <parent link="base_link"/>
    <child link="base_footprint"/>
    <origin rpy="0 0 0" xyz="0 0 -0.5549999999999999"/>
  </joint>
  <link name="front_left_wheel_link">
    <visual>
      <geometry>
        <cylinder length="0.11" radius="0.25"/>
      </geometry>
      <material name="Tyre">
        <color rgba="0.1 0.1 0.1 1.0"/>
      </material>
    </visual>
    <collision>
      <geometry>
        <cylinder length="0.11" radius="0.25"/>
      </geometry>
    </collision>
    <inertial>
      <mass value="8.0"/>
      <inertia ixx="0.13306666666666667" ixy="0" ixz="0" iyy="0.13306666666666667" iyz="0" izz="0.25"/>
    </inertial>
  </link>
  <link name="front_right_wheel_link">
    <visual>
      <geometry>
        <cylinder length="0.11" radius="0.25"/>
      </geometry>
      <material name="Tyre">
        <color rgba="0.1 0.1 0.1 1.0"/>
      </material>
    </visual>
    <collision>
      <geometry>
        <cylinder length="0.11" radius="0.25"/>
      </geometry>
    </collision>
    <inertial>
      <mass value="8.0"/>
      <inertia ixx="0.13306666666666667" ixy="0" ixz="0" iyy="0.13306666666666667" iyz="0" izz="0.25"/>
    </inertial>
  </link>
  <link name="rear_left_wheel_link">
    <visual>
      <geometry>
        <cylinder length="0.11" radius="0.25"/>
      </geometry>
      <material name="Tyre">
        <color rgba="0.1 0.1 0.1 1.0"/>
      </material>
    </visual>
    <collision>
      <geometry>
        <cylinder length="0.11" radius="0.25"/>
      </geometry>
    </collision>
    <inertial>
      <mass value="8.0"/>
      <inertia ixx="0.13306666666666667" ixy="0" ixz="0" iyy="0.13306666666666667" iyz="0" izz="0.25"/>
    </inertial>
  </link>
  <link name="rear_right_wheel_link">
    <visual>
      <geometry>
        <cylinder length="0.11" radius="0.25"/>
      </geometry>
      <material name="Tyre">
        <color rgba="0.1 0.1 0.1 1.0"/>
      </material>
    </visual>
    <collision>
      <geometry>
        <cylinder length="0.11" radius="0.25"/>
      </geometry>
    </collision>
    <inertial>
      <mass value="8.0"/>
      <inertia ixx="0.13306666666666667" ixy="0" ixz="0" iyy="0.13306666666666667" iyz="0" izz="0.25"/>
    </inertial>
  </link>
  <joint name="front_left_wheel_joint" type="continuous">
    <parent link="base_link"/>
    <child link="front_left_wheel_link"/>
    <origin rpy="-1.5707963267948966 0 0" xyz="1.19 0.533 -0.305"/>
    <axis xyz="0 0 1"/>
  </joint>
  <joint name="front_right_wheel_joint" type="continuous">
    <parent link="base_link"/>
    <child link="front_right_wheel_link"/>
    <origin rpy="1.5707963267948966 0 0" xyz="1.19 -0.533 -0.305"/>
    <axis xyz="0 0 1"/>
  </joint>
  <joint name="rear_left_wheel_joint" type="continuous">
    <parent link="base_link"/>
    <child link="rear_left_wheel_link"/>
    <origin rpy="-1.5707963267948966 0 0" xyz="0 0.533 -0.305"/>
    <axis xyz="0 0 1"/>
  </joint>
  <joint name="rear_right_wheel_joint" type="continuous">
    <parent link="base_link"/>
    <child link="rear_right_wheel_link"/>
    <origin rpy="1.5707963267948966 0 0" xyz="0 -0.533 -0.305"/>
    <axis xyz="0 0 1"/>
  </joint>
  <!-- <transmission name="drive_wheel_transmission">
    <type>transmission_interface/SimpleTransmission</type>
    <joint name="rear_left_wheel">
      <hardwareInterface>EffortJointInterface</hardwareInterface>
    </joint>
    <actuator name="drive_motor">
      <mechanicalReduction>100</mechanicalReduction>
      <hardwareInterface>EffortJointInterface</hardwareInterface>
    </actuator>
  </transmission> -->
  <!-- <ros2_control name="GazeboSystem" type="system">
    <hardware>
      <plugin>gazebo_ros2_control/GazeboSystem</plugin>
    </hardware>

    <joint name="slider_to_cart">
      <command_interface name="effort">
        <param name="min">-1000</param>
        <param name="max">1000</param>
      </command_interface>
      <state_interface name="position">
        <param name="initial_value">1.0</param>
      </state_interface>
      <state_interface name="velocity"/>
      <state_interface name="effort"/>
    </joint>

  </ros2_control> -->
  <!-- IMU sensors -->
  <!-- <link name="imu_link">
    <visual>
      <geometry>
        <box size="0.1 0.1 0.1"/>
      </geometry>
    </visual>

    <collision>
      <geometry>
        <box size="0.1 0.1 0.1"/>
      </geometry>
    </collision>

    <xacro:box_inertia m="0.1" l="0.1" w="0.1" h="0.1"/>
  </link>

  <joint name="imu_joint" type="fixed">
    <parent link="base_link"/>
    <child link="imu_link"/>
    <origin xyz="0 0 0.01"/>
  </joint>

  <gazebo reference="imu_link">
    <sensor name="imu_sensor" type="imu">
      <plugin filename="libgazebo_ros_imu_sensor.so" name="imu_plugin">
        <ros>
          <remapping>~/out:=/imu</remapping>
        </ros>
        <initial_orientation_as_reference>false</initial_orientation_as_reference>
      </plugin>
      <always_on>true</always_on>
      <update_rate>100</update_rate>
      <visualize>true</visualize>
      <imu>
        <angular_velocity>
          <x>
            <noise type="gaussian">
              <mean>0.0</mean>
              <stddev>2e-4</stddev>
              <bias_mean>0.0000075</bias_mean>
              <bias_stddev>0.0000008</bias_stddev>
            </noise>
          </x>
          <y>
            <noise type="gaussian">
              <mean>0.0</mean>
              <stddev>2e-4</stddev>
              <bias_mean>0.0000075</bias_mean>
              <bias_stddev>0.0000008</bias_stddev>
            </noise>
          </y>
          <z>
            <noise type="gaussian">
              <mean>0.0</mean>
              <stddev>2e-4</stddev>
              <bias_mean>0.0000075</bias_mean>
              <bias_stddev>0.0000008</bias_stddev>
            </noise>
          </z>
        </angular_velocity>
        <linear_acceleration>
          <x>
            <noise type="gaussian">
              <mean>0.0</mean>
              <stddev>1.7e-2</stddev>
              <bias_mean>0.1</bias_mean>
              <bias_stddev>0.001</bias_stddev>
            </noise>
          </x>
          <y>
            <noise type="gaussian">
              <mean>0.0</mean>
              <stddev>1.7e-2</stddev>
              <bias_mean>0.1</bias_mean>
              <bias_stddev>0.001</bias_stddev>
            </noise>
          </y>
          <z>
            <noise type="gaussian">
              <mean>0.0</mean>
              <stddev>1.7e-2</stddev>
              <bias_mean>0.1</bias_mean>
              <bias_stddev>0.001</bias_stddev>
            </noise>
          </z>
        </linear_acceleration>
      </imu>
    </sensor>
  </gazebo> -->
  <!-- <gazebo>
    <plugin name='diff_drive' filename='libgazebo_ros_diff_drive.so'>
      <left_joint>rear_left_wheel_joint</left_joint>
      <right_joint>rear_right_wheel_joint</right_joint>

      <wheel_separation>${wheel_track}</wheel_separation>
      <wheel_diameter>${2*wheel_radius}</wheel_diameter>

      <max_wheel_torque>20</max_wheel_torque>
      <max_wheel_acceleration>1.0</max_wheel_acceleration>

      <publish_odom>true</publish_odom>
      <publish_odom_tf>false</publish_odom_tf>
      <publish_wheel_tf>true</publish_wheel_tf>

      <odometry_frame>odom</odometry_frame>
      <robot_base_frame>base_link</robot_base_frame>
    </plugin>
  </gazebo> -->
</robot>
