<?xml version="1.0"?>
<robot name="beetle" xmlns:xacro="http://ros.org/wiki/xacro">
  <!-- Define arguments -->
  <xacro:arg name="beetle_controller_yaml_file"
             default="$(find beetle_gazebo)/config/ackermann_controller.yaml"/>
  <xacro:include filename="basic_shapes.xacro.xml"/>

  <!-- Define robot's inertial constants -->
  <xacro:property name="chassis_mass" value="40.0"/>
  <xacro:property name="wheel_mass" value="3.0"/>
  <xacro:property name="wheel_rim_mass" value="5.0"/>
  <xacro:property name="ring_gear_mass" value="2.0"/>
  <xacro:property name="spider_gear_mass" value="1.0"/>
  <xacro:property name="steering_link_mass" value="1.0"/>
  <xacro:property name="coupler_link_mass" value="2.0"/>
  <xacro:property name="steering_arm_mass" value="1.0"/>
  <xacro:property name="steering_slider_mass" value="1.0"/>
  <xacro:property name="steering_joint_friction" value="0.0075"/>
  <xacro:property name="joint_friction" value="0.0075"/>
  <xacro:property name="joint_damping" value="0.005"/>
  <xacro:property name="gravity" value="9.81"/>

  <!-- Define robot's distance constants -->
  <xacro:property name="tube_width" value="0.040"/>

  <xacro:property name="rear_xoff" value="-0.303"/>

  <xacro:property name="chassis_length_seg_1" value="1.240"/>
  <xacro:property name="chassis_length_seg_2" value="0.510"/>
  <xacro:property name="chassis_length_seg_3" value="0.240"/>

  <xacro:property name="chassis_width_seg_1" value="0.780"/>
  <xacro:property name="chassis_width_seg_2" value="0.380"/>

  <xacro:property name="chassis_total_length"
                  value="${chassis_length_seg_1+chassis_length_seg_2+chassis_length_seg_3}"/>
  <xacro:property name="chassis_xoff" value="${rear_xoff+chassis_total_length/2}"/>

  <xacro:property name="suspension_link_radius" value="0.010"/>
  <xacro:property name="suspension_zoff" value="${- tube_width/2 - 0.030}"/>
  <xacro:property name="suspension_xoff" value="${0.916}"/>
  <xacro:property name="rear_suspension_height" value="0.315"/>
  <xacro:property name="rear_suspension_height_1" value="0.195"/>
  <xacro:property name="front_suspension_height" value="0.205"/>

  <xacro:property name="rear_axle_radius" value="${0.028}"/>
  <xacro:property name="rear_axle_zoff"
                  value="${suspension_zoff - rear_suspension_height + 0.060}"/>
  <xacro:property name="front_axle_radius" value="${0.0245}"/>
  <xacro:property name="front_axle_zoff"
                  value="${suspension_zoff - front_suspension_height - 0.050}"/>

  <xacro:property name="wheel_track" value="1.066"/>
  <xacro:property name="wheel_base" value="1.190"/>
  <xacro:property name="pivot_distance" value="0.803"/>

  <xacro:property name="wheel_radius" value="0.250"/>
  <xacro:property name="wheel_width" value="0.110"/>

  <xacro:property name="wheel_rim_radius" value="0.143"/>
  <xacro:property name="wheel_rim_visual_width" value="0.01"/>

  <xacro:property name="ring_gear_radius" value="0.075"/>
  <xacro:property name="ring_gear_thickness" value="0.010"/>
  <xacro:property name="spider_gear_radius" value="0.025"/>
  <xacro:property name="spider_gear_thickness" value="0.040"/>
  <xacro:property name="ring_gear_yoff" value="0.035"/>

  <xacro:property name="steering_link_radius" value="0.020"/>
  <xacro:property name="steering_link_length" value="0.082"/>

  <xacro:property name="steering_slider_length" value="0.300"/>
  <xacro:property name="steering_slider_yoff" value="0.135"/>

  <xacro:property name="steering_slider_limit" value="0.050"/>
  <xacro:property name="steering_angle_limit" value="0.8531067212277285"/>

  <xacro:property name="control_box_width" value="0.300"/>
  <xacro:property name="control_box_height" value="0.100"/>
  <xacro:property name="control_box_thickness" value="0.0005"/>
  <xacro:property name="control_box_xoff" value="0.301"/>

  <xacro:property name="steering_arm_thickness" value="0.005"/>
  <xacro:property name="steering_arm_width" value="0.040"/>
  <!-- Steering paramters -->
  <!-- l1, l2, d, b, L = 0.0585 0.0452 0.0205 0.803 1.190 -->
  <xacro:property name="steering_arm_length" value="0.06965"/>
  <xacro:property name="steering_arm_length_2" value="0.13943"/>
  <xacro:property name="rack_distance" value="0.12922"/>
  <!-- Steering dependent variables -->
  <!-- <xacro:property name="ackermann_angle"
    value="${atan(pivot_distance/2*wheel_base)}"/> -->
  <xacro:property name="ackermann_angle"
    value="${radians(-10)}"/>
  <xacro:property name="v1"
      value="${steering_arm_length*cos(ackermann_angle)}"/>
  <xacro:property name="h1"
      value="${steering_arm_length*sin(ackermann_angle)}"/>
  <xacro:property name="v2"
    value="${(rack_distance - v1) if (rack_distance > v1) else
        (v1 - rack_distance)}"/>
  <xacro:property name="h2"
    value="${sqrt(steering_arm_length_2*steering_arm_length_2 - v2*v2)}"/>

  <xacro:property name="steering_arm_angle" value="${pi/2 - ackermann_angle}"/>
  <xacro:property name="steering_arm_angle_2"
    value="${ackermann_angle - acos(v2/steering_arm_length_2)}"/>

  <xacro:property name="coupler_link_length"
    value="${pivot_distance - 2*(h1 + h2)}"/>

  <!-- Define other macros  -->
  <!-- Robot Chassis -->
  <link name="base_link">
    <!-- Chassis visuals -->
    <xacro:macro name="vertical_tube_pair_visual" params="l w=${tube_width} x y">
      <visual>
        <origin xyz="${x+l/2} ${y-w/2} 0"/>
        <geometry>
          <box size="${l} ${w} ${w}"/>
        </geometry>
        <material name="Cyan">
          <color rgba="0 1.0 1.0 1.0"/>
        </material>
      </visual>
      <visual>
        <origin xyz="${x+l/2} ${-(y-w/2)} 0"/>
        <geometry>
          <box size="${l} ${w} ${w}"/>
        </geometry>
        <material name="Cyan">
          <color rgba="0 1.0 1.0 1.0"/>
        </material>
      </visual>
    </xacro:macro>
    <xacro:macro name="horizontal_tube_visual"
                 params="l=${chassis_width_seg_1-2*tube_width}
                         w=${tube_width}
                         x">
      <visual>
        <origin xyz="${x+w/2} 0 0"/>
        <geometry>
          <box size="${w} ${l} ${w}"/>
        </geometry>
        <material name="Cyan">
          <color rgba="0 1.0 1.0 1.0"/>
        </material>
      </visual>
    </xacro:macro>

    <!-- Seg 1 -->
    <xacro:vertical_tube_pair_visual l="${chassis_length_seg_1}"
                                     x="${rear_xoff}"
                                     y="${chassis_width_seg_1/2}" />
    <xacro:horizontal_tube_visual x="${rear_xoff}"/>
    <xacro:horizontal_tube_visual x="0"/>
    <xacro:horizontal_tube_visual x="${control_box_xoff-tube_width}"/>
    <xacro:horizontal_tube_visual x="${control_box_xoff+control_box_width}"/>
    <xacro:horizontal_tube_visual x="${rear_xoff+chassis_length_seg_1-tube_width}"/>
    <!-- Seg 2 -->
    <xacro:vertical_tube_pair_visual l="${chassis_length_seg_2}"
                                     x="${rear_xoff+chassis_length_seg_1}"
                                     y="${chassis_width_seg_2/2}" />
    <!-- Seg 3 -->
    <xacro:vertical_tube_pair_visual l="${chassis_length_seg_3}"
                                     x="${rear_xoff+chassis_length_seg_1+chassis_length_seg_2}"
                                     y="${chassis_width_seg_1/2}" />
    <xacro:horizontal_tube_visual x="${rear_xoff+chassis_length_seg_1+chassis_length_seg_2}"/>
    <xacro:horizontal_tube_visual x="${rear_xoff+chassis_total_length-tube_width}"/>

    <!-- Suspension link visuals -->
    <xacro:macro name="suspension_link_pair_visual"
                 params="x1 z1 x2 z2 y">
      <visual>
        <origin xyz="${(x1+x2)/2} ${y} ${(z1+z2)/2}"
                rpy="0 ${atan2(x2-x1, z2-z1)} 0"/>
        <geometry>
          <cylinder radius="${suspension_link_radius}"
                    length="${sqrt((x2-x1)**2 + (z2-z1)**2)}"/>
        </geometry>
        <material name="Cyan">
          <color rgba="0 1.0 1.0 1.0"/>
        </material>
      </visual>
      <visual>
        <origin xyz="${(x1+x2)/2} ${-y} ${(z1+z2)/2}"
                rpy="0 ${atan2(x2-x1, z2-z1)} 0"/>
        <geometry>
          <cylinder radius="${suspension_link_radius}"
                    length="${sqrt((x2-x1)**2 + (z2-z1)**2)}"/>
        </geometry>
        <material name="Cyan">
          <color rgba="0 1.0 1.0 1.0"/>
        </material>
      </visual>
    </xacro:macro>
    <!-- Shock absorber - front -->
    <xacro:suspension_link_pair_visual
      x1="${wheel_base}" x2="${wheel_base}"
      y="${(chassis_width_seg_2-tube_width)/2}"
      z1="${-tube_width/2}" z2="${front_axle_zoff+front_axle_radius}" />
    <xacro:suspension_link_pair_visual
      x1="${suspension_xoff}" x2="${wheel_base}"
      y="${(chassis_width_seg_2-tube_width)/2}"
      z1="${suspension_zoff}" z2="${suspension_zoff-front_suspension_height}" />

    <!-- Shock absorber - rear -->
    <xacro:suspension_link_pair_visual
      x1="0" x2="0" y="${(chassis_width_seg_1-tube_width)/2}"
      z1="${-tube_width/2}" z2="${rear_axle_zoff+rear_axle_radius}" />
    <xacro:suspension_link_pair_visual
      x1="${suspension_xoff}" x2="0"
      y="${(chassis_width_seg_1-tube_width)/2}"
      z1="${suspension_zoff}" z2="${suspension_zoff-rear_suspension_height}" />
    <xacro:suspension_link_pair_visual
      x1="${(rear_suspension_height-rear_suspension_height_1)*suspension_xoff/rear_suspension_height}"
      x2="0" y="${(chassis_width_seg_1-tube_width)/2}"
      z1="${suspension_zoff-rear_suspension_height_1}"
      z2="${suspension_zoff-rear_suspension_height_1}" />

    <!-- Axle visuals -->
    <xacro:macro name="axle_visual" params="r l x z">
      <visual>
        <origin xyz="${x} 0 ${z}" rpy="${pi/2} 0 0" />
        <geometry>
          <cylinder radius="${r}" length="${l}"/>
        </geometry>
        <material name="Cyan">
          <color rgba="0 1.0 1.0 1.0"/>
        </material>
      </visual>
    </xacro:macro>
    <!-- Front axle -->
    <xacro:axle_visual r="${front_axle_radius}"
                       l="${pivot_distance-2*steering_link_radius}"
                       x="${wheel_base}" z="${front_axle_zoff}" />

    <!-- Rear axle -->
    <xacro:axle_visual r="${rear_axle_radius}"
                       l="${wheel_track-wheel_width}"
                       x="0" z="${rear_axle_zoff}" />
    <!-- Control box visual -->
    <visual>
      <origin xyz="${control_box_xoff+control_box_width/2} 0
                   ${(tube_width-control_box_height)/2}0"/>
      <geometry>
        <box size="${control_box_width} ${control_box_width} ${control_box_height}"/>
      </geometry>
      <material name="Cyan">
        <color rgba="0 1.0 1.0 1.0"/>
      </material>
    </visual>


    <collision>
      <origin xyz="${chassis_xoff} 0 0"/>
      <geometry>
        <box size="${chassis_total_length} ${chassis_width_seg_1} ${tube_width}"/>
      </geometry>
    </collision>

    <xacro:box_inertia m="${chassis_mass}"
                       l="${chassis_total_length}"
                       w="${chassis_width_seg_1}"
                       h="${tube_width}"
                       x="${chassis_xoff}"/>
  </link>
  <gazebo reference="base_link">
    <material>Gazebo/Turquoise</material>
  </gazebo>

  <!-- Robot Footprint -->
  <link name="base_footprint"/>

  <joint name="base_joint" type="fixed">
    <parent link="base_link"/>
    <child link="base_footprint"/>
    <origin xyz="0 0 ${rear_axle_zoff - wheel_radius}" rpy="0 0 0"/>
  </joint>

  <!-- Steering links and joints -->
  <xacro:macro name="steer" params="prefix
                                    mass=${steering_link_mass}
                                    radius=${steering_link_radius}
                                    length=${steering_link_length}
                                    xoff=${wheel_base}
                                    yoff=${pivot_distance/2}
                                    zoff=${front_axle_zoff}
                                    reflect">
    <xacro:cylinder_link collision="0" zoff="0">
      <material name="Cyan">
        <color rgba="0 1.0 1.0 1.0"/>
      </material>
    </xacro:cylinder_link>
    <joint name="${prefix}_joint" type="revolute">
      <parent link="base_link"/>
      <child link="${prefix}_link"/>
      <origin xyz="${xoff} ${reflect*yoff} ${front_axle_zoff}"/>
      <axis xyz="0 0 1"/>
      <limit effort="30000.0" lower="-1.0" upper="1.0" velocity="0.5"/>
      <dynamics damping="${joint_damping}"
        friction="${steering_joint_friction}"/>
    </joint>

    <xacro:box_link prefix="${prefix}_arm"
                    xoff="${steering_arm_length/2}"
                    mass="${steering_arm_mass}"
                    length="${steering_arm_length+2*steering_link_radius}"
                    width="${steering_arm_width}"
                    height="${steering_arm_thickness}" collision="0">
      <material name="Cyan">
        <color rgba="0 1.0 1.0 1.0"/>
      </material>
    </xacro:box_link>
    <joint name="${prefix}_arm_joint" type="fixed">
      <parent link="${prefix}_link"/>
      <child link="${prefix}_arm_link"/>
      <origin xyz="0 0 ${steering_arm_thickness}"
              rpy="0 0 ${-(pi/2+steering_arm_angle)*reflect}"/>
    </joint>

    <xacro:box_link prefix="${prefix}_arm_2"
                    xoff="${steering_arm_length_2/2}"
                    mass="${steering_arm_mass}"
                    length="${steering_arm_length_2+2*steering_link_radius}"
                    width="${steering_arm_width}"
                    height="${steering_arm_thickness}" collision="0">
      <material name="Cyan">
        <color rgba="0 1.0 1.0 1.0"/>
      </material>
    </xacro:box_link>
    <joint name="${prefix}_arm_2_joint" type="continuous">
      <parent link="${prefix}_arm_link"/>
      <child link="${prefix}_arm_2_link"/>
      <origin xyz="${steering_arm_length} 0 ${steering_arm_thickness}"
              rpy="0 0 ${-steering_arm_angle_2*reflect}"/>
      <axis xyz="0 0 1"/>
      <dynamics damping="${joint_damping}" friction="${joint_friction}"/>
    </joint>
    <xacro:box_link prefix="${prefix}_coupler"
                    xoff="${coupler_link_length/4-steering_link_radius/2}"
                    mass="${coupler_link_mass/2}"
                    length="${coupler_link_length/2+steering_link_radius}"
                    width="${steering_arm_width}"
                    height="${steering_arm_thickness}" collision="0">
      <material name="Cyan">
        <color rgba="0 1.0 1.0 1.0"/>
      </material>
    </xacro:box_link>
    <joint name="${prefix}_coupler_joint" type="continuous">
      <parent link="${prefix}_arm_2_link"/>
      <child link="${prefix}_coupler_link"/>
      <origin xyz="${steering_arm_length_2} 0 ${steering_arm_thickness}"
              rpy="0 0 ${-(ackermann_angle-steering_arm_angle_2-pi/2)*reflect}"/>
      <axis xyz="0 0 1"/>
      <dynamics damping="${joint_damping}" friction="${joint_friction}"/>
    </joint>
  </xacro:macro>
  <xacro:steer prefix="left_steering" reflect="1"/>
  <xacro:steer prefix="right_steering" reflect="-1"/>
  <gazebo>
    <joint name="steering_coupler_joint" type="fixed">
      <pose>${coupler_link_length/2} 0.0 0 0 0 0</pose>
      <parent>left_steering_coupler_link</parent>
      <child>right_steering_coupler_link</child>
    </joint>
  </gazebo>

  <xacro:cylinder_link prefix="steering_slider" mass="${steering_slider_mass}"
    radius="${steering_arm_width/2}" length="${steering_slider_length}"
    collision="0">
    <material name="Cyan">
      <color rgba="0 1.0 1.0 1.0"/>
    </material>
  </xacro:cylinder_link>
  <joint name="steering_slider_joint" type="prismatic">
    <parent link="right_steering_coupler_link"/>
    <child link="steering_slider_link"/>
    <origin xyz="${steering_slider_yoff} 0 ${steering_arm_width}"
            rpy="0 ${-pi/2} 0"/>
    <axis xyz="0 0 1"/>
    <limit effort="30000" velocity="1.0" lower="${-steering_slider_limit}"
      upper="${steering_slider_limit}" />
  </joint>
  <gazebo>
    <joint name="steering_slider_base_joint" type="fixed">
      <pose>0 0 0 0 0 0</pose>
      <parent>base_link</parent>
      <child>steering_slider_link</child>
    </joint>
  </gazebo>

  <!-- Robot Wheels -->
  <xacro:macro name="wheel"
               params="prefix mass:=${wheel_mass}
                              radius:=${wheel_radius}
                              width:=${wheel_width}
                              rim_mass:=${wheel_rim_mass}
                              rim_radius:=${wheel_rim_radius}
                              rim_width:=${wheel_rim_visual_width}
                              xoff yoff zoff reflect
                              parent_link:=base_link
                              mimic:=''">
    <xacro:cylinder_link length="${width}" zoff="0" gazebo_material="DarkGrey">
      <material name="Tyre">
        <color rgba="0.1 0.1 0.1 1.0"/>
      </material>
    </xacro:cylinder_link>

    <joint name="${prefix}_joint" type="continuous">
      <xacro:unless value="${mimic == ''}">
        <mimic joint="${mimic}"/>
      </xacro:unless>
      <parent link="${parent_link}"/>
      <child link="${prefix}_link"/>
      <origin xyz="${xoff} ${reflect*yoff} ${zoff}"
              rpy="${-pi/2} 0 0"/>
      <axis xyz="0 0 1"/>
      <dynamics damping="${joint_damping}" friction="${joint_friction}"/>
    </joint>

    <xacro:macro name="wheel_rim"
                 params="side prefix=^ rim_mass:=^ rim_radius:=^ rim_width:=^ " >

      <xacro:cylinder_link prefix="${prefix}_${side}_rim"
                           mass="${rim_mass}"
                           radius="${rim_radius}"
                           length="${rim_width}"
                           zoff="0" collision="0">
        <material name="Cyan">
          <color rgba="0 1.0 1.0 1.0"/>
        </material>
      </xacro:cylinder_link>
      <joint name="${prefix}_${side}_rim_joint" type="fixed">
        <parent link="${prefix}_link"/>
        <child link="${prefix}_${side}_rim_link"/>
        <origin xyz="0 0 ${(1 if side == 'outer' else -1)*reflect*(width+rim_width)/2}" />
      </joint>
    </xacro:macro>
    <xacro:wheel_rim side="inner" />
    <xacro:wheel_rim side="outer" />

  </xacro:macro>
  <xacro:wheel prefix="front_left_wheel" xoff="0"
               yoff="${(wheel_track-pivot_distance)/2}"
               zoff="0"
               reflect="1"
               parent_link="left_steering_link"/>
  <xacro:wheel prefix="front_right_wheel" xoff="0"
               yoff="${(wheel_track-pivot_distance)/2}"
               zoff="0"
               reflect="-1"
               parent_link="right_steering_link"/>
  <xacro:wheel prefix="rear_left_wheel" xoff="0"
               yoff="${wheel_track/2}"
               zoff="${rear_axle_zoff}"
               reflect="1"/>
  <xacro:wheel prefix="rear_right_wheel" xoff="0"
               yoff="${wheel_track/2}"
               zoff="${rear_axle_zoff}"
               reflect="-1"/>

  <!-- Differential gearbox -->
  <link name="ring_gear_link">
    <visual>
      <geometry>
        <cylinder radius="${ring_gear_radius}"
          length="${ring_gear_thickness}"/>
      </geometry>
      <material name="Cyan">
        <color rgba="0 1.0 1.0 1.0"/>
      </material>
    </visual>

    <collision>
      <origin xyz="0 0 0" rpy="0 0 0"/>
      <geometry>
        <cylinder radius="${ring_gear_radius}"
          length="${ring_gear_thickness}"/>
      </geometry>
    </collision>

    <xacro:cylinder_inertia m="${ring_gear_mass}"
      r="${ring_gear_radius}" h="${ring_gear_thickness}"/>
  </link>

  <joint name="ring_gear_joint" type="continuous">
    <parent link="base_link"/>
    <child link="ring_gear_link"/>
    <origin xyz="0 ${ring_gear_yoff} ${rear_axle_zoff}" rpy="${-pi/2} 0 0"/>
    <axis xyz="0 0 1"/>
    <limit effort="1000" velocity="${2*pi}"/>
    <dynamics damping="${joint_damping}" friction="${joint_friction}"/>
  </joint>

  <link name="spider_gear_link">
    <visual>
      <geometry>
        <cylinder radius="${spider_gear_radius}"
          length="${spider_gear_thickness}"/>
      </geometry>
      <material name="Cyan">
        <color rgba="0 1.0 1.0 1.0"/>
      </material>
    </visual>

    <collision>
      <origin xyz="0 0 0" rpy="0 0 0"/>
      <geometry>
        <cylinder radius="${spider_gear_radius}"
          length="${spider_gear_thickness}"/>
      </geometry>
    </collision>

    <xacro:cylinder_inertia m="${spider_gear_mass}"
      r="${spider_gear_radius}" h="${spider_gear_thickness}"/>
  </link>

  <joint name="spider_gear_joint" type="continuous">
    <parent link="ring_gear_link"/>
    <child link="spider_gear_link"/>
    <origin xyz="0 0 ${ring_gear_yoff}" rpy="${-pi/2} 0 0"/>
    <axis xyz="0 0 1"/>
    <dynamics damping="${joint_damping}" friction="${joint_friction}"/>
  </joint>

  <gazebo>
    <joint name="gear_left_joint" type="gearbox">
        <parent>spider_gear_link</parent>
        <child>rear_left_wheel_link</child>
        <gearbox_ratio>1</gearbox_ratio>
        <gearbox_reference_body>ring_gear_link</gearbox_reference_body>
        <axis>
            <xyz>0 0 -1</xyz>
        </axis>
    </joint>
    <joint name="gear_right_joint" type="gearbox">
        <parent>spider_gear_link</parent>
        <child>rear_right_wheel_link</child>
        <gearbox_ratio>1</gearbox_ratio>
        <gearbox_reference_body>ring_gear_link</gearbox_reference_body>
        <axis>
            <xyz>0 0 1</xyz>
        </axis>
    </joint>
  </gazebo>

  <!-- <link name="dummy_link">
    <visual>
      <geometry>
        <cylinder radius="${spider_gear_radius}"
          length="${spider_gear_thickness}"/>
      </geometry>
      <material name="Cyan">
        <color rgba="0 1.0 1.0 1.0"/>
      </material>
    </visual>

    <xacro:cylinder_inertia m="${spider_gear_mass}"
      r="${spider_gear_radius}" h="${spider_gear_thickness}"/>
  </link>

  <joint name="dummy_joint" type="fixed">
    <parent link="rear_left_wheel_link"/>
    <child link="dummy_link"/>
    <origin xyz="0 ${wheel_radius*0.6} ${wheel_width}"/>
  </joint> -->

  <!-- Ackermann driver -->
  <ros2_control name="GazeboSystem" type="system">
    <hardware>
      <plugin>gazebo_ros2_control/GazeboSystem</plugin>
    </hardware>
    <joint name="ring_gear_joint">
      <command_interface name="effort"/>
      <state_interface name="position"/>
      <state_interface name="velocity"/>
      <state_interface name="effort"/>
    </joint>
    <joint name="steering_slider_joint">
      <command_interface name="effort"/>
      <state_interface name="position"/>
      <state_interface name="velocity"/>
      <state_interface name="effort"/>
    </joint>
  </ros2_control>

  <gazebo>
    <plugin filename="libgazebo_ros2_control.so" name="gazebo_ros2_control">
      <robot_param>robot_description</robot_param>
      <robot_param_node>robot_state_publisher</robot_param_node>
      <parameters>$(arg beetle_controller_yaml_file)</parameters>
    </plugin>
  </gazebo>

  <!-- IMU sensor -->
  <xacro:box_link prefix="imu" mass="0.01" length="0.01"
                  width="0.1" height="0.002" collision="0">
    <null/>
  </xacro:box_link>

  <joint name="imu_joint" type="fixed">
    <parent link="base_link"/>
    <child link="imu_link"/>
    <origin xyz="${control_box_xoff+control_box_width*0.3}
                 ${control_box_width*0.3}
                 ${tube_width/2-control_box_width*(1-0.3)}" />
  </joint>

  <gazebo reference="imu_link">
    <sensor name="imu_sensor" type="imu">
      <plugin filename="libgazebo_ros_imu_sensor.so" name="imu_plugin">
        <ros>
          <remapping>~/out:=/imu</remapping>
        </ros>
        <initial_orientation_as_reference>false</initial_orientation_as_reference>
      </plugin>
      <always_on>true</always_on>
      <update_rate>100</update_rate>
      <visualize>true</visualize>
      <imu>
        <angular_velocity>
          <x>
            <noise type="gaussian">
              <mean>0.0</mean>
              <stddev>2e-4</stddev>
              <bias_mean>0.0000075</bias_mean>
              <bias_stddev>0.0000008</bias_stddev>
            </noise>
          </x>
          <y>
            <noise type="gaussian">
              <mean>0.0</mean>
              <stddev>2e-4</stddev>
              <bias_mean>0.0000075</bias_mean>
              <bias_stddev>0.0000008</bias_stddev>
            </noise>
          </y>
          <z>
            <noise type="gaussian">
              <mean>0.0</mean>
              <stddev>2e-4</stddev>
              <bias_mean>0.0000075</bias_mean>
              <bias_stddev>0.0000008</bias_stddev>
            </noise>
          </z>
        </angular_velocity>
        <linear_acceleration>
          <x>
            <noise type="gaussian">
              <mean>0.0</mean>
              <stddev>1.7e-2</stddev>
              <bias_mean>0.1</bias_mean>
              <bias_stddev>0.001</bias_stddev>
            </noise>
          </x>
          <y>
            <noise type="gaussian">
              <mean>0.0</mean>
              <stddev>1.7e-2</stddev>
              <bias_mean>0.1</bias_mean>
              <bias_stddev>0.001</bias_stddev>
            </noise>
          </y>
          <z>
            <noise type="gaussian">
              <mean>0.0</mean>
              <stddev>1.7e-2</stddev>
              <bias_mean>0.1</bias_mean>
              <bias_stddev>0.001</bias_stddev>
            </noise>
          </z>
        </linear_acceleration>
      </imu>
    </sensor>
  </gazebo>

  <!-- GPS -->
  <xacro:box_link prefix="gps" mass="0.01" length="0.01"
                  width="0.01" height="0.002" collision="0">
    <null/>
  </xacro:box_link>

  <joint name="gps_joint" type="fixed">
    <parent link="base_link"/>
    <child link="gps_link"/>
    <origin xyz="${control_box_xoff+control_box_width*0.3}
                 ${-control_box_width*0.3}
                 ${tube_width/2-control_box_width*(1-0.3)}"/>
  </joint>

  <gazebo reference="gps_link">
    <sensor name="gps_sensor" type="gps">
      <always_on>true</always_on>
      <update_rate>1.0</update_rate>
      <plugin name="gps_controller" filename="libgazebo_ros_gps_sensor.so">
        <ros>
          <!-- <namespace>/br</namespace> -->
          <remapping>gps_controller/out:=gps</remapping>
        </ros>
        <frame_name>gps_link</frame_name>
        <offset>0 0 0</offset>
        <drift>0.001 0.001 0.001</drift>
        <gaussianNoise>0.05 0.05 0.05</gaussianNoise>
        <velocityDrift>0.001 0.001 0.001</velocityDrift>
        <velocityGaussianNoise>0.5 0.5 0.5</velocityGaussianNoise>
      </plugin>
    </sensor>
  </gazebo>

</robot>
